Traceback (most recent call last):
  File "/home/ubuntu/test_codellm/gen_prediction.py", line 210, in <module>
    main(
  File "/home/ubuntu/test_codellm/gen_prediction.py", line 116, in main
    raw_prediction = model.chat(prompt, temperature=0.1)
  File "/home/ubuntu/test_codellm/models/GPT4.py", line 13, in chat
    response = client.chat.completions.create(
  File "/home/ubuntu/.local/lib/python3.10/site-packages/openai/_utils/_utils.py", line 299, in wrapper
    return func(*args, **kwargs)
  File "/home/ubuntu/.local/lib/python3.10/site-packages/openai/resources/chat/completions.py", line 598, in create
    return self._post(
  File "/home/ubuntu/.local/lib/python3.10/site-packages/openai/_base_client.py", line 1063, in post
    return cast(ResponseT, self.request(cast_to, opts, stream=stream, stream_cls=stream_cls))
  File "/home/ubuntu/.local/lib/python3.10/site-packages/openai/_base_client.py", line 842, in request
    return self._request(
  File "/home/ubuntu/.local/lib/python3.10/site-packages/openai/_base_client.py", line 873, in _request
    return self._retry_request(
  File "/home/ubuntu/.local/lib/python3.10/site-packages/openai/_base_client.py", line 933, in _retry_request
    return self._request(
  File "/home/ubuntu/.local/lib/python3.10/site-packages/openai/_base_client.py", line 873, in _request
    return self._retry_request(
  File "/home/ubuntu/.local/lib/python3.10/site-packages/openai/_base_client.py", line 933, in _retry_request
    return self._request(
  File "/home/ubuntu/.local/lib/python3.10/site-packages/openai/_base_client.py", line 885, in _request
    raise self._make_status_error_from_response(err.response) from None
openai.RateLimitError: Error code: 429 - {'error': {'message': 'You exceeded your current quota, please check your plan and billing details. For more information on this error, read the docs: https://platform.openai.com/docs/guides/error-codes/api-errors.', 'type': 'insufficient_quota', 'param': None, 'code': 'insufficient_quota'}}
