[ERROR] [12-11 23:30:34] logging.py:86 [t:140243605417984]: api request failed with error code: 17, err msg: Open api daily request limit reached
Traceback (most recent call last):
  File "/home/ubuntu/test_codellm/gen_prediction.py", line 210, in <module>
    main(
  File "/home/ubuntu/test_codellm/gen_prediction.py", line 116, in main
    raw_prediction = model.chat(prompt, temperature=0.1)
  File "/home/ubuntu/test_codellm/models/Wenxin.py", line 79, in chat
    resp = chat_comp.do(
  File "/home/ubuntu/.local/lib/python3.10/site-packages/qianfan/resources/llm/chat_completion.py", line 265, in do
    return self._do(
  File "/home/ubuntu/.local/lib/python3.10/site-packages/qianfan/resources/llm/base.py", line 100, in _do
    resp = self._client.llm(
  File "/home/ubuntu/.local/lib/python3.10/site-packages/qianfan/resources/api_requestor.py", line 394, in llm
    return self._with_retry(retry_config, _helper)
  File "/home/ubuntu/.local/lib/python3.10/site-packages/qianfan/resources/api_requestor.py", line 267, in _with_retry
    return func(*args)
  File "/home/ubuntu/.local/lib/python3.10/site-packages/qianfan/resources/api_requestor.py", line 331, in retry_wrapper
    return func(*args)
  File "/home/ubuntu/.local/lib/python3.10/site-packages/qianfan/resources/api_requestor.py", line 392, in _helper
    return self._request(req, data_postprocess=data_postprocess)
  File "/home/ubuntu/.local/lib/python3.10/site-packages/qianfan/resources/api_requestor.py", line 104, in _request
    return data_postprocess(self._parse_response(body, response))
  File "/home/ubuntu/.local/lib/python3.10/site-packages/qianfan/resources/api_requestor.py", line 194, in _parse_response
    self._check_error(body)
  File "/home/ubuntu/.local/lib/python3.10/site-packages/qianfan/resources/api_requestor.py", line 233, in _check_error
    raise errors.APIError(error_code, err_msg)
qianfan.errors.APIError: api return error, code: 17, msg: Open api daily request limit reached
